Workbook

Sheet Data
A1: Icono part.abiertas/comp. | B1: Asignación | C1: Nº documento | D1: División | E1: Clase de documento | F1: Fecha de documento | G1: Clave contabiliz. | H1: Importe en moneda local | I1: Moneda local | J1: Indicador impuestos | K1: Doc.compensación | L1: Nombre | M1: Fe.contabilización | N1: Documento compras | O1: Posición | P1: CONCATENA | Q1: Fecha de entrega | R1: Grupo de compras | S1: Proveedor/Centro suministrador
C2: 1900011914 | E2: GG | F2: 46100 | G2: 96 | H2: -4678042.2 | I2: ARS | J2: C1 | L2: AURELIA SACIYF | M2: 46213 | N2: 4500121598 | O2: 20 | P2: =_xlfn.CONCAT(N2:O2) -> 450012159820 | Q2: {=VLOOKUP(P2,Hoja1!C:F,{2,3,4},FALSE)} -> 46091 | R2: C03 | S2: 1000000754 AURELIA SACIYF
C3: 1900011914 | E3: GG | F3: 46100 | G3: 96 | H3: -175105.98 | I3: ARS | J3: C1 | L3: AURELIA SACIYF | M3: 46213 | N3: 4500121598 | O3: 40 | P3: =_xlfn.CONCAT(N3:O3) -> 450012159840 | Q3: {=VLOOKUP(P3,Hoja1!C:F,{2,3,4},FALSE)} -> 46091 | R3: C03 | S3: 1000000754 AURELIA SACIYF
C4: 1900000693 | D4: 8000 | E4: GR | F4: 45966 | G4: 86 | H4: 16833600 | I4: ARS | J4: C1 | L4: LA LILY S.A | M4: 45973 | N4: 4500112140 | O4: 10 | P4: =_xlfn.CONCAT(N4:O4) -> 450011214010 | Q4: {=VLOOKUP(P4,Hoja1!C:F,{2,3,4},FALSE)} -> 46053 | R4: C14 | S4: 1000000681 LA LILY S.A
C5: 1900004712 | D5: 3000 | E5: GR | F5: 46058 | G5: 86 | H5: 37297.16 | I5: ARS | J5: C1 | L5: TIGRE ARGENTINA S.A. | M5: 46071 | N5: 4500120177 | O5: 30 | P5: =_xlfn.CONCAT(N5:O5) -> 450012017730 | Q5: {=VLOOKUP(P5,Hoja1!C:F,{2,3,4},FALSE)} -> 46097 | R5: C09 | S5: 1000000417 TIGRE ARGENTINA S.A.
C6: 1900004715 | D6: 3000 | E6: GR | F6: 46058 | G6: 86 | H6: 76107.8 | I6: ARS | J6: C1 | L6: TIGRE ARGENTINA S.A. | M6: 46071 | N6: 4500120178 | O6: 20 | P6: =_xlfn.CONCAT(N6:O6) -> 450012017820 | Q6: {=VLOOKUP(P6,Hoja1!C:F,{2,3,4},FALSE)} -> 46097 | R6: C09 | S6: 1000000417 TIGRE ARGENTINA S.A.
C7: 1900005391 | E7: GR | F7: 46083 | G7: 86 | H7: 8694649.1 | I7: ARS | J7: C9 | L7: SERVICIOS CIPOLLETTI SRL | M7: 46085 | N7: 4500119831 | O7: 10 | P7: =_xlfn.CONCAT(N7:O7) -> 450011983110 | Q7: {=VLOOKUP(P7,Hoja1!C:F,{2,3,4},FALSE)} -> 46140 | R7: C21 | S7: 1000006796 SERVICIOS CIPOLLETTI SRL
C8: 1900005470 | D8: 3000 | E8: GR | F8: 46085 | G8: 86 | H8: 10683.25 | I8: ARS | J8: C1 | L8: EQUIPEL SRL | M8: 46087 | N8: 4500120570 | O8: 40 | P8: =_xlfn.CONCAT(N8:O8) -> 450012057040 | Q8: {=VLOOKUP(P8,Hoja1!C:F,{2,3,4},FALSE)} -> 46092 | R8: C11 | S8: 1000001211 EQUIPEL SRL
C9: 1900005470 | D9: 3000 | E9: GR | F9: 46085 | G9: 86 | H9: 23262.6 | I9: ARS | J9: C1 | L9: EQUIPEL SRL | M9: 46087 | N9: 4500120570 | O9: 100 | P9: =_xlfn.CONCAT(N9:O9) -> 4500120570100 | Q9: {=VLOOKUP(P9,Hoja1!C:F,{2,3,4},FALSE)} -> 46092 | R9: C11 | S9: 1000001211 EQUIPEL SRL
C10: 1900005622 | E10: GR | F10: 46086 | G10: 86 | H10: 15403403 | I10: ARS | J10: C1 | L10: GASES ROSARIO S.R.L. | M10: 46091 | N10: 4500121166 | O10: 20 | P10: =_xlfn.CONCAT(N10:O10) -> 450012116620 | Q10: {=VLOOKUP(P10,Hoja1!C:F,{2,3,4},FALSE)} -> 46090 | R10: C27 | S10: 1000000010 GASES ROSARIO S.R.L.
C11: 1900006657 | D11: 3000 | E11: GR | F11: 46113 | G11: 86 | H11: 861230 | I11: ARS | J11: C1 | L11: CICCIOELEC SA | M11: 46113 | N11: 4500122510 | O11: 80 | P11: =_xlfn.CONCAT(N11:O11) -> 450012251080 | Q11: {=VLOOKUP(P11,Hoja1!C:F,{2,3,4},FALSE)} -> 46122 | R11: C11 | S11: 1000003063 CICCIOELEC SA
C12: 1900006657 | D12: 3000 | E12: GR | F12: 46113 | G12: 86 | H12: 2498916 | I12: ARS | J12: C1 | L12: CICCIOELEC SA | M12: 46113 | N12: 4500122510 | O12: 170 | P12: =_xlfn.CONCAT(N12:O12) -> 4500122510170 | Q12: {=VLOOKUP(P12,Hoja1!C:F,{2,3,4},FALSE)} -> 46122 | R12: C11 | S12: 1000003063 CICCIOELEC SA
C13: 1900007490 | E13: GR | F13: 46123 | G13: 86 | H13: 6511283.5 | I13: ARS | J13: C1 | L13: BUNTECH DEL LAGO SOCIEDAD ANONIMA | M13: 46127 | N13: 4500123321 | O13: 20 | P13: =_xlfn.CONCAT(N13:O13) -> 450012332120 | Q13: {=VLOOKUP(P13,Hoja1!C:F,{2,3,4},FALSE)} -> 46142 | R13: C14 | S13: 1000001146 BUNTECH DEL LAGO SOCIEDAD ANONIMA
C14: 1900007491 | E14: GR | F14: 46123 | G14: 86 | H14: 6443268.7 | I14: ARS | J14: C1 | L14: BUNTECH DEL LAGO SOCIEDAD ANONIMA | M14: 46127 | N14: 4500123321 | O14: 20 | P14: =_xlfn.CONCAT(N14:O14) -> 450012332120 | Q14: {=VLOOKUP(P14,Hoja1!C:F,{2,3,4},FALSE)} -> 46142 | R14: C14 | S14: 1000001146 BUNTECH DEL LAGO SOCIEDAD ANONIMA
C15: 1900008023 | E15: GR | F15: 45743 | G15: 86 | H15: 1320000 | I15: ARS | J15: C1 | L15: CASELLA GUILLERMO CESAR | M15: 45771 | N15: 4500096318 | O15: 10 | P15: =_xlfn.CONCAT(N15:O15) -> 450009631810 | Q15: {=VLOOKUP(P15,Hoja1!C:F,{2,3,4},FALSE)} -> 45751 | R15: C17 | S15: 1000000850 CASELLA GUILLERMO CESAR
C16: 1900008202 | D16: 3000 | E16: GR | F16: 46135 | G16: 86 | H16: 15102.88 | I16: ARS | J16: C1 | L16: FELRRO SRL | M16: 46136 | N16: 4500125959 | O16: 30 | P16: =_xlfn.CONCAT(N16:O16) -> 450012595930 | Q16: {=VLOOKUP(P16,Hoja1!C:F,{2,3,4},FALSE)} -> 46156 | R16: C11 | S16: 1000012787 FELRRO SRL
C17: 1900008202 | D17: 3000 | E17: GR | F17: 46135 | G17: 86 | H17: 16967507 | I17: ARS | J17: C1 | L17: FELRRO SRL | M17: 46136 | N17: 4500120744 | O17: 20 | P17: =_xlfn.CONCAT(N17:O17) -> 450012074420 | Q17: {=VLOOKUP(P17,Hoja1!C:F,{2,3,4},FALSE)} -> 46121 | R17: C11 | S17: 1000012787 FELRRO SRL
C18: 1900009204 | E18: GR | F18: 45797 | G18: 86 | H18: 601692 | I18: ARS | J18: C1 | L18: LOPEZ DIESEL S.A. | M18: 45800 | N18: 4500099273 | O18: 150 | P18: =_xlfn.CONCAT(N18:O18) -> 4500099273150 | Q18: {=VLOOKUP(P18,Hoja1!C:F,{2,3,4},FALSE)} -> 45838 | R18: C03 | S18: 1000003040 LOPEZ DIESEL S.A.
C19: 1900009592 | D19: 3000 | E19: GR | F19: 46160 | G19: 86 | H19: 1213116 | I19: ARS | J19: C1 | L19: RANAWEL SA | M19: 46161 | N19: 4500125561 | O19: 20 | P19: =_xlfn.CONCAT(N19:O19) -> 450012556120 | Q19: {=VLOOKUP(P19,Hoja1!C:F,{2,3,4},FALSE)} -> 46171 | R19: C28 | S19: 1000011064 RANAWEL SA
C20: 1900009882 | E20: GR | F20: 46168 | G20: 86 | H20: 1007826.3 | I20: ARS | J20: C9 | L20: GLOBAL OIL S.R.L. | M20: 46171 | N20: 4500125979 | O20: 10 | P20: =_xlfn.CONCAT(N20:O20) -> 450012597910 | Q20: {=VLOOKUP(P20,Hoja1!C:F,{2,3,4},FALSE)} -> 46254 | R20: C21 | S20: 1000000808 GLOBAL OIL S.R.L.
C21: 1900009882 | E21: GR | F21: 46168 | G21: 86 | H21: 212200.14 | I21: ARS | J21: C9 | L21: GLOBAL OIL S.R.L. | M21: 46171 | N21: 4500125979 | O21: 10 | P21: =_xlfn.CONCAT(N21:O21) -> 450012597910 | Q21: {=VLOOKUP(P21,Hoja1!C:F,{2,3,4},FALSE)} -> 46254 | R21: C21 | S21: 1000000808 GLOBAL OIL S.R.L.
C22: 1900010163 | D22: 8000 | E22: GR | F22: 46164 | G22: 86 | H22: 6529863 | I22: ARS | J22: C1 | L22: LA LILY S.A | M22: 46177 | N22: 4500128112 | O22: 10 | P22: =_xlfn.CONCAT(N22:O22) -> 450012811210 | Q22: {=VLOOKUP(P22,Hoja1!C:F,{2,3,4},FALSE)} -> 46234 | R22: C14 | S22: 1000000681 LA LILY S.A
C23: 1900010553 | E23: GR | F23: 46113 | G23: 86 | H23: 359559.08 | I23: ARS | J23: C1 | L23: ALFREDO CRIOLANI E HIJOS S.A. | M23: 46182 | N23: 4500123477 | O23: 80 | P23: =_xlfn.CONCAT(N23:O23) -> 450012347780 | Q23: {=VLOOKUP(P23,Hoja1!C:F,{2,3,4},FALSE)} -> 46122 | R23: C29 | S23: 1000000229 ALFREDO CRIOLANI E HIJOS S.A.
C24: 1900011121 | E24: GR | F24: 46195 | G24: 86 | H24: 529946.03 | I24: ARS | J24: C9 | L24: GLOBAL OIL S.R.L. | M24: 46199 | N24: 4500129914 | O24: 10 | P24: =_xlfn.CONCAT(N24:O24) -> 450012991410 | Q24: {=VLOOKUP(P24,Hoja1!C:F,{2,3,4},FALSE)} -> 46295 | R24: C21 | S24: 1000000808 GLOBAL OIL S.R.L.
C25: 1900011346 | E25: GR | F25: 46203 | G25: 86 | H25: 445128.41 | I25: ARS | J25: C9 | L25: GLOBAL OIL S.R.L. | M25: 46205 | N25: 4500129914 | O25: 10 | P25: =_xlfn.CONCAT(N25:O25) -> 450012991410 | Q25: {=VLOOKUP(P25,Hoja1!C:F,{2,3,4},FALSE)} -> 46295 | R25: C21 | S25: 1000000808 GLOBAL OIL S.R.L.
C26: 1900011895 | D26: Z000 | E26: GR | F26: 46206 | G26: 86 | H26: 51332266 | I26: ARS | J26: C1 | L26: GRIMALDI G.H. S.R.L. | M26: 46213 | N26: 4500130791 | O26: 20 | P26: =_xlfn.CONCAT(N26:O26) -> 450013079120 | Q26: {=VLOOKUP(P26,Hoja1!C:F,{2,3,4},FALSE)} -> 46325 | R26: C26 | S26: 1000000483 GRIMALDI G.H. S.R.L.
C27: 1900011895 | D27: Z000 | E27: GR | F27: 46206 | G27: 86 | H27: 10163612 | I27: ARS | J27: C1 | L27: GRIMALDI G.H. S.R.L. | M27: 46213 | N27: 4500130791 | O27: 30 | P27: =_xlfn.CONCAT(N27:O27) -> 450013079130 | Q27: {=VLOOKUP(P27,Hoja1!C:F,{2,3,4},FALSE)} -> 46325 | R27: C26 | S27: 1000000483 GRIMALDI G.H. S.R.L.
C28: 1900011895 | D28: Z000 | E28: GR | F28: 46206 | G28: 86 | H28: 40504122 | I28: ARS | J28: C1 | L28: GRIMALDI G.H. S.R.L. | M28: 46213 | N28: 4500130791 | O28: 40 | P28: =_xlfn.CONCAT(N28:O28) -> 450013079140 | Q28: {=VLOOKUP(P28,Hoja1!C:F,{2,3,4},FALSE)} -> 46325 | R28: C26 | S28: 1000000483 GRIMALDI G.H. S.R.L.
C29: 1900012054 | E29: GR | F29: 46181 | G29: 86 | H29: 5511903.7 | I29: ARS | J29: C1 | L29: FERRARO Y CIA S.A. | M29: 46219 | N29: 4500119904 | O29: 10 | P29: =_xlfn.CONCAT(N29:O29) -> 450011990410 | Q29: {=VLOOKUP(P29,Hoja1!C:F,{2,3,4},FALSE)} -> 46284 | R29: C21 | S29: 1000004906 FERRARO Y CIA S.A.
C30: 1900012054 | E30: GR | F30: 46181 | G30: 86 | H30: 860288.07 | I30: ARS | J30: C9 | L30: FERRARO Y CIA S.A. | M30: 46219 | N30: 4500119904 | O30: 10 | P30: =_xlfn.CONCAT(N30:O30) -> 450011990410 | Q30: {=VLOOKUP(P30,Hoja1!C:F,{2,3,4},FALSE)} -> 46284 | R30: C21 | S30: 1000004906 FERRARO Y CIA S.A.
C31: 1900012395 | D31: Z000 | E31: GR | F31: 46219 | G31: 86 | H31: 23160151 | I31: ARS | J31: C1 | L31: MADETEC S.A. | M31: 46230 | N31: 4500132626 | O31: 10 | P31: =_xlfn.CONCAT(N31:O31) -> 450013262610 | Q31: {=VLOOKUP(P31,Hoja1!C:F,{2,3,4},FALSE)} -> 46317 | R31: C19 | S31: 1000000015 MADETEC S.A.
C32: 1900013217 | D32: Z000 | E32: GR | F32: 46245 | G32: 86 | H32: 198347.04 | I32: ARS | J32: C1 | L32: EMILIA MASSARELLI SRL | M32: 46246 | N32: 4500134840 | O32: 10 | P32: =_xlfn.CONCAT(N32:O32) -> 450013484010 | Q32: {=VLOOKUP(P32,Hoja1!C:F,{2,3,4},FALSE)} -> 46305 | R32: C26 | S32: 1000003158 EMILIA MASSARELLI SRL
C33: 1900013217 | D33: Z000 | E33: GR | F33: 46245 | G33: 86 | H33: 4958677.7 | I33: ARS | J33: C1 | L33: EMILIA MASSARELLI SRL | M33: 46246 | N33: 4500134840 | O33: 20 | P33: =_xlfn.CONCAT(N33:O33) -> 450013484020 | Q33: {=VLOOKUP(P33,Hoja1!C:F,{2,3,4},FALSE)} -> 46305 | R33: C26 | S33: 1000003158 EMILIA MASSARELLI SRL
C34: 1900013834 | E34: GR | F34: 46246 | G34: 86 | H34: 9387640 | I34: ARS | J34: C1 | L34: J.M.F. VIAL & PARTS SAS | M34: 46262 | N34: 4500132643 | O34: 10 | P34: =_xlfn.CONCAT(N34:O34) -> 450013264310 | Q34: {=VLOOKUP(P34,Hoja1!C:F,{2,3,4},FALSE)} -> 46301 | R34: C38 | S34: 1000002834 J.M.F. VIAL & PARTS SAS
C35: 1900014527 | E35: GR | F35: 46197 | G35: 86 | H35: 2221863.8 | I35: ARS | J35: C9 | L35: GLOBAL OIL S.R.L. | M35: 46276 | N35: 4500135995 | O35: 10 | P35: =_xlfn.CONCAT(N35:O35) -> 450013599510 | Q35: {=VLOOKUP(P35,Hoja1!C:F,{2,3,4},FALSE)} -> 46295 | R35: C21 | S35: 1000000808 GLOBAL OIL S.R.L.
C36: 1900014527 | E36: GR | F36: 46197 | G36: 86 | H36: 467680.33 | I36: ARS | J36: C9 | L36: GLOBAL OIL S.R.L. | M36: 46276 | N36: 4500135995 | O36: 10 | P36: =_xlfn.CONCAT(N36:O36) -> 450013599510 | Q36: {=VLOOKUP(P36,Hoja1!C:F,{2,3,4},FALSE)} -> 46295 | R36: C21 | S36: 1000000808 GLOBAL OIL S.R.L.
C37: 1900014616 | E37: GR | F37: 46279 | G37: 86 | H37: 6120000 | I37: ARS | J37: C1 | L37: CARLOS BOERO S.R.L. | M37: 46279 | N37: 4500134748 | O37: 10 | P37: =_xlfn.CONCAT(N37:O37) -> 450013474810 | Q37: {=VLOOKUP(P37,Hoja1!C:F,{2,3,4},FALSE)} -> 46308 | R37: C03 | S37: 1000000098 CARLOS BOERO S.R.L.
C38: 1900014664 | E38: GR | F38: 45498 | G38: 86 | H38: 1364160 | I38: ARS | J38: C1 | L38: ANDRES N. BERTOTTO SAIC | M38: 45498 | N38: 4500078458 | O38: 10 | P38: =_xlfn.CONCAT(N38:O38) -> 450007845810 | Q38: {=VLOOKUP(P38,Hoja1!C:F,{2,3,4},FALSE)} -> 45562 | R38: C03 | S38: 1000001457 ANDRES N. BERTOTTO SAIC
C39: 1900014774 | E39: GR | F39: 46281 | G39: 86 | H39: 9200000 | I39: ARS | J39: C1 | L39: EMPRESA DEL OESTE SAT | M39: 46283 | N39: 4500137489 | O39: 10 | P39: =_xlfn.CONCAT(N39:O39) -> 450013748910 | Q39: {=VLOOKUP(P39,Hoja1!C:F,{2,3,4},FALSE)} -> 46301 | R39: C03 | S39: 1000013552 EMPRESA DEL OESTE SAT
C40: 1900014837 | D40: 3000 | E40: GR | F40: 46281 | G40: 86 | H40: 9960978 | I40: ARS | J40: C1 | L40: DASTEC SRL | M40: 46287 | N40: 4500138303 | O40: 10 | P40: =_xlfn.CONCAT(N40:O40) -> 450013830310 | Q40: {=VLOOKUP(P40,Hoja1!C:F,{2,3,4},FALSE)} -> 46353 | R40: C20 | S40: 1000000968 DASTEC SRL
...

Sheet Hoja1
A1: Documento compras | B1: Posición | D1: Fecha de entrega | E1: Grupo de compras | F1: Proveedor/Centro suministrador
A2: 4500130230 | B2: 10 | C2: =_xlfn.CONCAT(A2:B2) -> 450013023010 | D2: 46402 | E2: C25 | F2: 1000000065 SA IMPORTADORA Y EXP. DE LA PA
A3: 4500139115 | B3: 10 | C3: =_xlfn.CONCAT(A3:B3) -> 450013911510 | D3: 46397 | E3: C26 | F3: 1000002120 INGEAP S.A.S.
A4: 4500137748 | B4: 10 | C4: =_xlfn.CONCAT(A4:B4) -> 450013774810 | D4: 46336 | E4: C15 | F4: 1000011965 DIRECTO SUR S. R. L.
A5: 4500139377 | B5: 10 | C5: =_xlfn.CONCAT(A5:B5) -> 450013937710 | D5: 46402 | E5: C26 | F5: 1000002120 INGEAP S.A.S.
A6: 4500139125 | B6: 10 | C6: =_xlfn.CONCAT(A6:B6) -> 450013912510 | D6: 46350 | E6: C26 | F6: 1000002120 INGEAP S.A.S.
A7: 4500137571 | B7: 10 | C7: =_xlfn.CONCAT(A7:B7) -> 450013757110 | D7: 46387 | E7: C15 | F7: 1000010190 ANDREANI LOGISTICA SA
A8: 4500139153 | B8: 10 | C8: =_xlfn.CONCAT(A8:B8) -> 450013915310 | D8: 46326 | E8: C26 | F8: 1000002120 INGEAP S.A.S.
A9: 4500136303 | B9: 10 | C9: =_xlfn.CONCAT(A9:B9) -> 450013630310 | D9: 46356 | E9: C21 | F9: 1000006796 SERVICIOS CIPOLLETTI SRL
A10: 4500136126 | B10: 10 | C10: =_xlfn.CONCAT(A10:B10) -> 450013612610 | D10: 46325 | E10: C25 | F10: 1000012180 ANDRADE ERIC ALEXIS
A11: 4500139224 | B11: 10 | C11: =_xlfn.CONCAT(A11:B11) -> 450013922410 | D11: 46326 | E11: C21 | F11: 1000000808 GLOBAL OIL S.R.L.
A12: 4500108692 | B12: 10 | C12: =_xlfn.CONCAT(A12:B12) -> 450010869210 | D12: 46330 | E12: C12 | F12: 1000011488 RM DEL SUR S. R. L
A13: 4500129761 | B13: 10 | C13: =_xlfn.CONCAT(A13:B13) -> 450012976110 | D13: 47299 | E13: C25 | F13: 1000000527 SEGURIDAD Y RESGUARDO SRL
... A3658: 4500140170 | B3658: 10 | C3658: =_xlfn.CONCAT(A3658:B3658) -> 450014017010 | D3658: 46359 | E3658: C25 | F3658: 1000011590 NOALE CLAUDIA ELISABETH VIVIANA
